#VRML_SIM R2025a utf8

EXTERNPROTO "https://raw.githubusercontent.com/cyberbotics/webots/R2025a/projects/objects/backgrounds/protos/TexturedBackground.proto"
EXTERNPROTO "https://raw.githubusercontent.com/cyberbotics/webots/R2025a/projects/objects/backgrounds/protos/TexturedBackgroundLight.proto"
EXTERNPROTO "https://raw.githubusercontent.com/cyberbotics/webots/R2025a/projects/objects/solids/protos/SolidBox.proto"
EXTERNPROTO "https://raw.githubusercontent.com/cyberbotics/webots/R2025a/projects/objects/floors/protos/RectangleArena.proto"
EXTERNPROTO "https://raw.githubusercontent.com/cyberbotics/webots/R2025a/projects/objects/factory/conveyors/protos/ConveyorBelt.proto"
EXTERNPROTO "https://raw.githubusercontent.com/cyberbotics/webots/R2025a/projects/robots/universal_robots/protos/UR5e.proto"
EXTERNPROTO "https://raw.githubusercontent.com/cyberbotics/webots/R2025a/projects/appearances/protos/ThreadMetalPlate.proto"
EXTERNPROTO "https://raw.githubusercontent.com/cyberbotics/webots/R2025a/projects/objects/factory/containers/protos/MetalStorageBox.proto"
EXTERNPROTO "https://raw.githubusercontent.com/cyberbotics/webots/R2025a/projects/appearances/protos/HammeredCopper.proto"
EXTERNPROTO "https://raw.githubusercontent.com/cyberbotics/webots/R2025a/projects/appearances/protos/Copper.proto"

WorldInfo {
}
Viewpoint {
  orientation 0.21109020971043274 0.4063110403915119 -0.8890175824022677 1.0577176211718768
  position -2.063646392018767 2.4840401757805517 1.116207624465197
}
TexturedBackground {
  texture "factory"
}
MetalStorageBox {
  translation 1.22354e-07 0.38 -1.1
  rotation 0 0 1 -1.5707953071795862
}
TexturedBackgroundLight {
}
SolidBox {
  translation 0.00478279 -0.829953 -0.75
  rotation 0 0 1 -1.55
  size 1 1 0.5
  appearance PBRAppearance {
    roughness 0.5
    metalness 0
  }
}
SolidBox {
  translation 0.000656362 0.330219 -0.91
  rotation 0 0 1 -1.55
  name "box(2)"
  size 0.5 0.9 0.5
  appearance PBRAppearance {
    baseColor 0.3 0.2 0.2
    roughness 0.5
    metalness 0
  }
}
SolidBox {
  translation -0.0628001 2.41924 -0.75
  rotation 0 0 1 -1.55
  name "box(1)"
  size 0.5 0.5 0.5
  appearance PBRAppearance {
    roughness 0.5
    metalness 0
  }
}
SolidBox {
  translation 0.0948262 -5.15908 -0.87
  rotation 0 0 1 -1.55
  name "box(3)"
  size 0.5 0.5 0.5
  appearance PBRAppearance {
    roughness 0.5
    metalness 0
  }
}
UR5e {
  hidden position_0_0 9.761104235221413e-05
  hidden rotation_1 0 0 0.9999999999999999 9.761104111460728e-05
  hidden position_1_0 0.0009207196498725301
  hidden rotation_2 0 1 0 1.5717167196498705
  hidden position_2_0 0.000260500860061843
  hidden rotation_3 0 1 0 0.00026050086082366023
  hidden position_3_0 1.9745602970918375e-05
  hidden rotation_4 0 1 0 1.5708157456029688
  hidden position_4_0 -4.1871833893429665e-07
  hidden rotation_5 0 0 -1 4.182955279236503e-07
  hidden position_5_0 1.2363454459713394e-06
  hidden rotation_6 0 1 0 1.2363474674637241e-06
  translation -0.1 2.45 -0.48
}
UR5e {
  hidden position_0_0 0.00040328314554541355
  hidden rotation_1 0 0 1 0.00040328314531332875
  hidden position_1_0 0.0009716872501647854
  hidden rotation_2 0 1 0 1.5717676872501616
  hidden position_2_0 0.00027635798109840886
  hidden rotation_3 0 1 0 0.00027635798183737944
  hidden position_3_0 6.66212931788099e-06
  hidden rotation_4 0 1 0 1.5708026621293147
  hidden position_4_0 -1.6558128048025313e-06
  hidden rotation_5 0 0 -1 1.6558402041303512e-06
  hidden position_5_0 9.056110376467897e-11
  translation 0 -5.07 -0.57
  name "UR5e(1)"
}
RectangleArena {
  translation 0 0 -1
  floorSize 20 20
  floorAppearance ThreadMetalPlate {
  }
}
DEF TARGET_BOX Solid {
  translation -0.08510851165579601 0.0356090649074315 -0.4508629328301903
  rotation -0.8851576588103467 0.21138996436895433 0.41449994211516844 0.0022118224601829608
  children [
    Shape {
      appearance PBRAppearance {
        baseColor 1 0.1 0.1
      }
      geometry Box {
        size 0.1 0.1 0.1
      }
    }
  ]
  boundingObject Box {
    size 0.1 0.1 0.1
  }
  physics Physics {
  }
  linearVelocity 4.715947001854293e-06 0.3926540429463452 0.001862117154784878
  angularVelocity 0.04084507343580453 -0.002765700428648113 0.002799772313590458
}
DEF SKIP_BOX1 Solid {
  translation 7.500426515487887 -0.0010888260608714578 -0.46943939776884097
  rotation 0.00029922052683259393 -0.7070870967264119 0.7071264017911438 3.1410155431039293
  children [
    Shape {
      appearance PBRAppearance {
        baseColor 0.1 1 0.1
      }
      geometry Box {
        size 0.1 0.1 0.1
      }
    }
  ]
  name "solid(1)"
  boundingObject Box {
    size 0.1 0.1 0.1
  }
  physics Physics {
  }
  linearVelocity 3.3280886414388526e-07 6.356904510084053e-07 -8.526868535989249e-05
  angularVelocity -2.1487941620662562e-05 1.2735843280786684e-05 1.5387070551042526e-07
}
DEF SKIP_BOX2 Solid {
  translation 1.9262232725603847 4.7307158707626556e-05 -0.4558411120779302
  rotation 0.9998360471094547 0.013974511399310746 0.011514856998272607 1.5709328414436712
  children [
    Shape {
      appearance PBRAppearance {
        baseColor 0.1 1 0.1
      }
      geometry Box {
        size 0.1 0.1 0.1
      }
    }
  ]
  name "solid(3)"
  boundingObject Box {
    size 0.1 0.1 0.1
  }
  physics Physics {
  }
  linearVelocity 0.2000015949642386 -4.275980185632024e-06 -0.0004558390244762582
  angularVelocity -3.258840701650302e-06 1.3910236449726656e-05 9.730864578432268e-07
}
DEF SKIP_BOX3 Solid {
  translation 0.9269384139322748 5.017620459553816e-05 -0.4534027491615198
  rotation 0.001819714165368921 -0.7070859813690388 0.7071252389723759 -3.141431270613214
  children [
    Shape {
      appearance PBRAppearance {
        baseColor 0.1 1 0.1
      }
      geometry Box {
        size 0.1 0.1 0.1
      }
    }
  ]
  name "solid(4)"
  boundingObject Box {
    size 0.1 0.1 0.1
  }
  physics Physics {
  }
  linearVelocity 0.2000016461671298 -5.1386610651306186e-06 -0.00043484939365722537
  angularVelocity -5.271700922806061e-06 1.3910292561473307e-05 9.780160993097344e-07
}
DEF SKIP_BOX4 Solid {
  translation -1.0731454734858272 5.626170379080693e-05 -0.4485223286100302
  rotation 0.5237343663608423 0.6708283565600319 -0.5250634528583892 1.9620680150903287
  children [
    Shape {
      appearance PBRAppearance {
        baseColor 0.1 1 0.1
      }
      geometry Box {
        size 0.1 0.1 0.1
      }
    }
  ]
  name "solid(2)"
  boundingObject Box {
    size 0.1 0.1 0.1
  }
  physics Physics {
  }
  linearVelocity 0.20000174865020867 -6.8653300287670335e-06 -0.00039283832439141586
  angularVelocity -9.300470867355415e-06 1.391040556664496e-05 9.878828550015133e-07
}
ConveyorBelt {
  hidden translation_1 -0.00029631655974590027 3.22970826198421e-06 0.3741343436184893
  hidden rotation_1 -0.023837829915897297 0.999712075907111 0.002742836195501587 0.0024408094434204635
  hidden linearVelocity_1 -9.579396284679058e-07 -6.524509693473874e-06 7.114112292902064e-05
  hidden angularVelocity_1 8.916379093302032e-06 2.1134425451835784e-05 9.4314151456057e-07
  translation 0.05 -0.08 -1
  size 15 0.3 0.5
  appearance HammeredCopper {
  }
  borderHeight 0
  speed 0.2
}
ConveyorBelt {
  hidden translation_1 0 0 0.3749529120153945
  translation 0.15 2.85 -1.04
  name "conveyor belt(1)"
  size 15 0.3 0.5
  borderHeight 0
  speed 0.2
}
ConveyorBelt {
  hidden translation_1 0 0 0.3749529120153945
  translation 0.25 -4.53 -1.05
  name "conveyor belt(2)"
  size 15 0.3 0.5
  borderHeight 0
  speed 0.2
}
Robot {
  translation 0 -0.57 -0.38
  children [
    Camera {
      translation -0.140001 0.395656 0.0347439
      rotation -0.3574069463669815 0.35740494636728165 0.8628568705184134 1.71778
      name "color_sensor"
    }
    SliderJoint {
      jointParameters JointParameters {
        position -0.2068929264841381
        axis 0 -1 0
        minStop -10
        maxStop 10
        dampingConstant 1
      }
      device [
        LinearMotor {
          name "pusher_motor"
          maxVelocity 15
        }
      ]
      endPoint Solid {
        translation 4.372442695216253e-06 0.20689292647776317 -0.003608497233218211
        rotation -0.4583894863051319 -0.47143373133559635 -0.7534117836906417 7.644745909202539e-07
        children [
          Shape {
            appearance PBRAppearance {
            }
            geometry Box {
              size 0.3 0.7 0.2
            }
          }
        ]
        boundingObject Box {
          size 0.3 0.7 0.2
        }
        physics Physics {
          density 600
        }
        linearVelocity 3.3593125556454585e-05 0.3196613557350232 4.489514905644105e-05
        angularVelocity 9.640009982161217e-06 3.331808294651359e-06 -2.2088404378338488e-07
      }
    }
  ]
  name "sorter_controller"
  controller "arm"
  supervisor TRUE
}
Transform {
  translation 0 -0.85 -0.42
  scale 7 8 6
  children [
    Shape {
      appearance Copper {
      }
      geometry Cylinder {
        height 0.1
        radius 0.05
      }
    }
  ]
}
