#VRML_SIM R2025a utf8

EXTERNPROTO "https://raw.githubusercontent.com/cyberbotics/webots/R2025a/projects/objects/backgrounds/protos/TexturedBackground.proto"
EXTERNPROTO "https://raw.githubusercontent.com/cyberbotics/webots/R2025a/projects/objects/backgrounds/protos/TexturedBackgroundLight.proto"
EXTERNPROTO "https://raw.githubusercontent.com/cyberbotics/webots/R2025a/projects/objects/solids/protos/SolidBox.proto"
EXTERNPROTO "https://raw.githubusercontent.com/cyberbotics/webots/R2025a/projects/objects/floors/protos/RectangleArena.proto"
EXTERNPROTO "https://raw.githubusercontent.com/cyberbotics/webots/R2025a/projects/objects/factory/conveyors/protos/ConveyorBelt.proto"
EXTERNPROTO "https://raw.githubusercontent.com/cyberbotics/webots/R2025a/projects/robots/universal_robots/protos/UR5e.proto"
EXTERNPROTO "https://raw.githubusercontent.com/cyberbotics/webots/R2025a/projects/appearances/protos/ThreadMetalPlate.proto"
EXTERNPROTO "https://raw.githubusercontent.com/cyberbotics/webots/R2025a/projects/objects/factory/containers/protos/MetalStorageBox.proto"
EXTERNPROTO "https://raw.githubusercontent.com/cyberbotics/webots/R2025a/projects/appearances/protos/HammeredCopper.proto"
EXTERNPROTO "https://raw.githubusercontent.com/cyberbotics/webots/R2025a/projects/appearances/protos/Copper.proto"

WorldInfo {
}
Viewpoint {
  orientation 0.17698906625557795 0.38678490334179005 -0.9050261371766346 0.936251332985428
  position -4.361235471507197 4.883564971884573 2.1172444521053984
}
TexturedBackground {
  texture "factory"
}
MetalStorageBox {
  translation 1.22354e-07 0.38 -1.1
  rotation 0 0 1 -1.5707953071795862
}
TexturedBackgroundLight {
}
SolidBox {
  translation 0 -0.6 -0.75
  rotation 0 0 1 -1.55
  size 0.5 0.5 0.5
  appearance PBRAppearance {
    roughness 0.5
    metalness 0
  }
}
SolidBox {
  translation 0.000656362 0.330219 -0.91
  rotation 0 0 1 -1.55
  name "box(2)"
  size 0.5 0.9 0.5
  appearance PBRAppearance {
    baseColor 0.3 0.2 0.2
    roughness 0.5
    metalness 0
  }
}
SolidBox {
  translation -0.0628001 2.41924 -0.75
  rotation 0 0 1 -1.55
  name "box(1)"
  size 0.5 0.5 0.5
  appearance PBRAppearance {
    roughness 0.5
    metalness 0
  }
}
UR5e {
  hidden position_0_0 2.0111707632200027e-06
  hidden rotation_1 0 0 1 2.011159994459593e-06
  hidden position_1_0 0.00017744616695724674
  hidden rotation_2 0 1 0 1.5709734461669569
  hidden position_2_0 5.435083167933757e-05
  hidden rotation_3 0 0.9999999999999999 0 5.435083287647113e-05
  hidden position_3_0 1.3817216388286216e-07
  hidden rotation_4 0 1 0 1.570796138172163
  hidden position_4_0 -8.973881863916488e-09
  hidden position_5_0 8.752439119961123e-09
  translation -0.1 2.45 -0.48
}
RectangleArena {
  translation 0 0 -1
  floorSize 20 20
  floorAppearance ThreadMetalPlate {
  }
}
DEF TARGET_BOX Solid {
  translation 0.6656312890123254 0.0002568829150246057 -0.45061735320802837
  rotation 3.901370819972899e-05 5.3977120516303346e-05 0.9999999977822004 1.451659688840988
  children [
    Shape {
      appearance PBRAppearance {
        baseColor 1 0.1 0.1
      }
      geometry Box {
        size 0.1 0.1 0.1
      }
    }
  ]
  boundingObject Box {
    size 0.1 0.1 0.1
  }
  physics Physics {
  }
  linearVelocity 0.2000010743983984 6.921379360712171e-08 -2.1282787656305536e-05
  angularVelocity -2.191789838448143e-12 6.328095794436791e-06 -8.334263714880866e-12
}
DEF SKIP_BOX Solid {
  translation 1.664014253366994 2.6593079166605482e-05 -0.4507044988346661
  rotation 0.707128508986216 0.0051552655578800234 0.7070662592826493 -3.1312937865531616
  children [
    Shape {
      appearance PBRAppearance {
        baseColor 0.1 1 0.1
      }
      geometry Box {
        size 0.1 0.1 0.1
      }
    }
  ]
  name "solid(1)"
  boundingObject Box {
    size 0.1 0.1 0.1
  }
  physics Physics {
  }
  linearVelocity 0.20000107385251834 6.920590829855944e-08 -2.7551067320580477e-05
  angularVelocity -2.190758144226367e-12 6.328095798186716e-06 -8.334579206298595e-12
}
ConveyorBelt {
  hidden translation_1 -2.132278091898643e-06 -7.75062945213012e-08 0.37482948015645945
  hidden rotation_1 -0.09980039822441936 0.9949996878278792 0.003937224488224145 8.772745793482039e-05
  hidden linearVelocity_1 3.248385804690509e-15 -1.9710831374249233e-16 9.663381206337363e-16
  hidden angularVelocity_1 -2.1720710921101072e-12 6.278432112898499e-06 -7.897894518227874e-12
  translation 0.05 -0.08 -1
  size 7 0.3 0.5
  appearance HammeredCopper {
  }
  borderHeight 0
  speed 0.2
}
ConveyorBelt {
  hidden translation_1 0.012244649606706154 0.0019143987302530086 0.3869315407889541
  hidden rotation_1 -0.7460500955138794 0.5199177870318137 0.4160465715658205 0.000677061098228316
  translation 0.15 2.85 -1.04
  name "conveyor belt(1)"
  size 7 0.3 0.5
  borderHeight 0
  speed 0.2
}
Robot {
  translation 0 -0.49 -0.38
  children [
    Camera {
      translation -1.2116e-06 0.275773 -0.0263077
      rotation -0.1294279597735375 0.1294279597735375 0.9831056944488314 1.58784
      name "color_sensor"
    }
    SliderJoint {
      jointParameters JointParameters {
        position 5.551115121586557e-17
        axis 0 -1 0
        minStop -10
        maxStop 10
        dampingConstant 1
      }
      device [
        LinearMotor {
          name "pusher_motor"
          maxVelocity 15
        }
      ]
      endPoint Solid {
        translation 4.372442683833874e-06 -6.375011629700096e-12 -0.0010471872815165373
        rotation -0.4583894909214531 -0.4714337268944652 -0.7534117836609445 7.644745909202539e-07
        children [
          Shape {
            appearance PBRAppearance {
            }
            geometry Box {
              size 0.3 0.6 0.2
            }
          }
        ]
        boundingObject Box {
          size 0.3 0.3 0.2
        }
        physics Physics {
        }
        linearVelocity -2.2578736500769875e-36 5.55105961005648e-16 -2.169823082012035e-06
      }
    }
  ]
  name "sorter_controller"
  controller "arm"
  supervisor TRUE
}
Transform {
  translation 0 -0.61 -0.42
  scale 5 5 6
  children [
    Shape {
      appearance Copper {
      }
      geometry Cylinder {
        height 0.1
        radius 0.05
      }
    }
  ]
}
